#VRML_SIM R2023a utf8

EXTERNPROTO "https://raw.githubusercontent.com/cyberbotics/webots/R2023a/projects/objects/backgrounds/protos/TexturedBackground.proto"
EXTERNPROTO "https://raw.githubusercontent.com/cyberbotics/webots/R2023a/projects/objects/backgrounds/protos/TexturedBackgroundLight.proto"
EXTERNPROTO "https://raw.githubusercontent.com/cyberbotics/webots/R2023a/projects/objects/floors/protos/RectangleArena.proto"

WorldInfo {
}
Viewpoint {
  orientation -0.5358574279210646 -0.2864061253422887 0.7942470322942594 3.944510206642942
  position 0.8155572092971732 1.8734276637058387 4.843387454751643
}
TexturedBackground {
}
TexturedBackgroundLight {
}
RectangleArena {
}
Robot {
  translation 0 0 0.73
  children [
    HingeJoint {
      endPoint Solid {
        translation 0.1 0 0
        rotation 1 0 0 0
        children [
          Shape {
            appearance PBRAppearance {
              baseColor 0.5 0.5 0.9
            }
            geometry Box {
              size 0.1 0.1 0.1
            }
          }
        ]
        name "solid(1)"
        boundingObject Box {
          size 0.1 0.1 0.1
        }
        physics Physics {
        }
      }
    }
    Solid {
      children [
        Shape {
          appearance PBRAppearance {
          }
          geometry Box {
            size 0.1 0.1 0.1
          }
        }
      ]
      boundingObject Box {
        size 0.1 0.1 0.1
      }
      physics Physics {
        density -1
        mass 1.0000000000000002
        centerOfMass [
          0 0 0
        ]
        inertiaMatrix [
          0.0016666666666666674 0.0016666666666666674 0.0016666666666666674
          0 0 0
        ]
      }
    }
  ]
  boundingObject Box {
    size 0.1 0.1 0.1
  }
  physics Physics {
  }
}
